Workbook
Name SN: 'TECH 1'!$A$10:$A$109

Sheet TECH 1
B1: LAGOS STATE GOVERNMENT.
B2: GOVERNMENT TECHNICAL COLLEGE.
B3: ODOMOLA,EPE.
B4: BROADSHEET -TECH 1 | D4: SESSION: | H4: 2024/2025
A5: S/N | D5: TECH 1 | M5: SECTION: | R5: ELECTRICAL INSTALLATION & MAINTENANCE
B6: SUBJECT | C6: 1ST TERM | DI6: 2ND TERM | IX6: 3RD TERM
D7: CRAFT PRACTICE | J7: BUILDING/ENG. DRAWING | P7: BASIC ELECTRICITY | V7: CABLE JOINTING | AB7: DOMESTIC INSTALLATION | AT7: ENGLISH LANGUAGE | AZ7: MATHEMATICS | BF7: PHYSICS | BL7: CHEMISTRY | BR7: I.C.T | BX7: ECONOMICS | CD7: ENTREPRENEURSHIP | DI7: CRAFT PRACTICE | DQ7: BUILDING/ENG. DRAWING | DY7: BASIC ELECTRICITY | EG7: CABLE JOINTING | EO7: DOMESTIC INSTALLATION | EW7: BATTERY CHARGING | FE7: INDUSTRIAL INSTALLATION | FM7: ENGLISH LANGUAGE | FU7: MATHEMATICS | GC7: PHYSICS | GK7: CHEMISTRY | GS7: I.C.T | HA7: ECONOMICS | HI7: ENTREPRENEURSHIP | HQ7: SIWES | IX7: CRAFT PRACTICE | JG7: BUILDING/ENG. DRAWING | JP7: BASIC ELECTRICITY | JY7: CABLE JOINTING | KH7: DOMESTIC INSTALLATION | KQ7: BATTERY CHARGING | KZ7: INDUSTRIAL INSTALLATION | LI7: ENGLISH LANGUAGE | LR7: MATHEMATICS | MA7: PHYSICS | MJ7: CHEMISTRY | MS7: I.C.T | NB7: ECONOMICS | NK7: ENTREPRENEURSHIP
B8: NAME | C8: GENDER | D8: CA (40) | E8: EXAM (60) | F8: TOTAL (100%) | G8: % | H8: GRADE | I8: SUBJECT POSITION | J8: CA (41) | K8: EXAM (61) | L8: TOTAL (101%) | M8: % | N8: GRADE | O8: SUBJECT POSITION | P8: CA (42) | Q8: EXAM (62) | R8: TOTAL (102%) | S8: % | T8: GRADE | U8: SUBJECT POSITION | V8: CA (43) | W8: EXAM (63) | X8: TOTAL (103%) | Y8: % | Z8: GRADE | AA8: SUBJECT POSITION | AB8: CA (44) | AC8: EXAM (64) | AD8: TOTAL (104%) | AE8: % | AF8: GRADE | AG8: SUBJECT POSITION | AH8: CA (45) | AI8: EXAM (65) | AJ8: TOTAL (105%) | AK8: % | AL8: GRADE | AM8: SUBJECT POSITION | AN8: CA (46) | AO8: EXAM (66) | AP8: TOTAL (106%) | AQ8: % | AR8: GRADE | AS8: SUBJECT POSITION | AT8: CA (47) | AU8: EXAM (67) | AV8: TOTAL (107%) | AW8: % | AX8: GRADE | AY8: SUBJECT POSITION | AZ8: CA (48) | BA8: EXAM (68) | BB8: TOTAL (108%) | BC8: % | BD8: GRADE | BE8: SUBJECT POSITION | BF8: CA (49) | BG8: EXAM (69) | BH8: TOTAL (109%) | BI8: % | BJ8: GRADE | BK8: SUBJECT POSITION | BL8: CA (50) | BM8: EXAM (70) | BN8: TOTAL (110%) | BO8: % | BP8: GRADE | BQ8: SUBJECT POSITION | BR8: CA (51) | BS8: EXAM (71) | BT8: TOTAL (111%) | BU8: % | BV8: GRADE | BW8: SUBJECT POSITION | BX8: CA (52) | BY8: EXAM (72) | BZ8: TOTAL (112%) | CA8: % | CB8: GRADE | CC8: SUBJECT POSITION | CD8: CA (53) | CE8: EXAM (73) | CF8: TOTAL (113%) | CG8: % | CH8: GRADE | CI8: SUBJECT POSITION | CJ8: CA (54) | CK8: EXAM (74) | CL8: TOTAL (114%) | CM8: % | CN8: GRADE | CO8: SUBJECT POSITION | CP8: CA (55) | CQ8: EXAM (75) | CR8: TOTAL (115%) | CS8: % | CT8: GRADE | CU8: SUBJECT POSITION | CV8: CA (56) | CW8: EXAM (76) | CX8: TOTAL (116%) | CY8: % | CZ8: GRADE | DA8: SUBJECT POSITION | DC8: TOTAL MARK | DD8: AVERAGE SCORE | DE8: CLASS POSITION | DG8: % | DI8: CA (40) | DJ8: EXAM (60) | DK8: TOTAL (100%) | DL8: B/F 2ND TERM | DM8: GD TOTAL (200) | DN8: AV % | DO8: GRADE | DP8: SUBJECT POSITION | DQ8: CA (40) | DR8: EXAM (60) | DS8: TOTAL (100%) | DT8: B/F 2ND TERM | DU8: GD TOTAL (200) | DV8: AV % | DW8: GRADE | DX8: SUBJECT POSITION | DY8: CA (40) | DZ8: EXAM (60) | EA8: TOTAL (100%) | EB8: B/F 2ND TERM | EC8: GD TOTAL (200) | ED8: AV % | EE8: GRADE | EF8: SUBJECT POSITION | EG8: CA (40) | EH8: EXAM (60) | EI8: TOTAL (100%) | EJ8: B/F 2ND TERM | EK8: GD TOTAL (200) | EL8: AV % | EM8: GRADE | EN8: SUBJECT POSITION | EO8: CA (40) | EP8: EXAM (60) | EQ8: TOTAL (100%) | ER8: B/F 2ND TERM | ES8: GD TOTAL (200) | ET8: AV % | EU8: GRADE | EV8: SUBJECT POSITION | EW8: CA (40) | EX8: EXAM (60) | EY8: TOTAL (100%) | EZ8: B/F 2ND TERM | FA8: GD TOTAL (200) | FB8: AV % | FC8: GRADE | FD8: SUBJECT POSITION | FE8: CA (40) | FF8: EXAM (60) | FG8: TOTAL (100%) | FH8: B/F 2ND TERM | FI8: GD TOTAL (200) | FJ8: AV % | FK8: GRADE | FL8: SUBJECT POSITION | FM8: CA (40) | FN8: EXAM (60) | FO8: TOTAL (100%) | FP8: B/F 2ND TERM | FQ8: GD TOTAL (200) | FR8: AV % | FS8: GRADE | FT8: SUBJECT POSITION | FU8: CA (40) | FV8: EXAM (60) | FW8: TOTAL (100%) | FX8: B/F 2ND TERM | FY8: GD TOTAL (200) | FZ8: AV % | GA8: GRADE | GB8: SUBJECT POSITION | GC8: CA (40) | GD8: EXAM (60) | GE8: TOTAL (100%) | GF8: B/F 2ND TERM | GG8: GD TOTAL (200) | GH8: AV % | GI8: GRADE | GJ8: SUBJECT POSITION | GK8: CA (40) | GL8: EXAM (60) | GM8: TOTAL (100%) | GN8: B/F 2ND TERM | GO8: GD TOTAL (200) | GP8: AV % | GQ8: GRADE | GR8: SUBJECT POSITION | GS8: CA (40) | GT8: EXAM (60) | GU8: TOTAL (100%) | GV8: B/F 2ND TERM | GW8: GD TOTAL (200) | GX8: AV % | GY8: GRADE | GZ8: SUBJECT POSITION | HA8: CA (40) | HB8: EXAM (60) | HC8: TOTAL (100%) | HD8: B/F 2ND TERM | HE8: GD TOTAL (200) | HF8: AV % | HG8: GRADE | HH8: SUBJECT POSITION | HI8: CA (40) | HJ8: EXAM (60) | HK8: TOTAL (100%) | HL8: B/F 2ND TERM | HM8: GD TOTAL (200) | HN8: AV % | HO8: GRADE | HP8: SUBJECT POSITION | HQ8: CA (40) | HR8: EXAM (60) | HS8: TOTAL (100%) | HT8: B/F 2ND TERM | HU8: GD TOTAL (200) | HV8: AV % | HW8: GRADE | HX8: SUBJECT POSITION | HY8: CA (40) | HZ8: EXAM (60) | IA8: TOTAL (100%) | IB8: B/F 2ND TERM | IC8: GD TOTAL (200) | ID8: AV % | IE8: GRADE | IF8: SUBJECT POSITION | IG8: CA (40) | IH8: EXAM (60) | II8: TOTAL (100%) | IJ8: B/F 2ND TERM | IK8: GD TOTAL (200) | IL8: AV % | IM8: GRADE | IN8: SUBJECT POSITION | IO8: TOTAL MARKS | IP8: AVERAGE SCORE | IQ8: CLASS POSITION | IX8: CA (40) | IY8: EXAM (60) | IZ8: TOTAL (100%) | JA8: B/F 1ST TERM | JB8: B/F 2ND TERM | JC8: GD TOTAL (300) | JD8: AV % | JE8: GRADE | JF8: SUBJECT POSITION | JG8: CA (40) | JH8: EXAM (60) | JI8: TOTAL (100%) | JJ8: B/F 1ST TERM | JK8: B/F 2ND TERM | JL8: GD TOTAL (300) | JM8: AV % | JN8: GRADE | JO8: SUBJECT POSITION | JP8: CA (40) | JQ8: EXAM (60) | JR8: TOTAL (100%) | JS8: B/F 1ST TERM | JT8: B/F 2ND TERM | JU8: GD TOTAL (300) | JV8: AV % | JW8: GRADE | JX8: SUBJECT POSITION | JY8: CA (40) | JZ8: EXAM (60) | KA8: TOTAL (100%) | KB8: B/F 1ST TERM | KC8: B/F 2ND TERM | KD8: GD TOTAL (300) | KE8: AV % | KF8: GRADE | KG8: SUBJECT POSITION | KH8: CA (40) | KI8: EXAM (60) | KJ8: TOTAL (100%) | KK8: B/F 1ST TERM | KL8: B/F 2ND TERM | KM8: GD TOTAL (300) | KN8: AV % | KO8: GRADE | KP8: SUBJECT POSITION | KQ8: CA (40) | KR8: EXAM (60) | KS8: TOTAL (100%) | KT8: B/F 1ST TERM | KU8: B/F 2ND TERM | KV8: GD TOTAL (300) | KW8: AV % | KX8: GRADE | KY8: SUBJECT POSITION | KZ8: CA (40) | LA8: EXAM (60) | LB8: TOTAL (100%) | LC8: B/F 1ST TERM | LD8: B/F 2ND TERM | LE8: GD TOTAL (300) | LF8: AV % | LG8: GRADE | LH8: SUBJECT POSITION | LI8: CA (40) | LJ8: EXAM (60) | LK8: TOTAL (100%) | LL8: B/F 1ST TERM | LM8: B/F 2ND TERM | LN8: GD TOTAL (300) | LO8: AV % | LP8: GRADE | LQ8: SUBJECT POSITION | LR8: CA (40) | LS8: EXAM (60) | LT8: TOTAL (100%) | LU8: B/F 1ST TERM | LV8: B/F 2ND TERM | LW8: GD TOTAL (300) | LX8: AV % | LY8: GRADE | LZ8: SUBJECT POSITION | MA8: CA (40) | MB8: EXAM (60) | MC8: TOTAL (100%) | MD8: B/F 1ST TERM | ME8: B/F 2ND TERM | MF8: GD TOTAL (300) | MG8: AV % | MH8: GRADE | MI8: SUBJECT POSITION | MJ8: CA (40) | MK8: EXAM (60) | ML8: TOTAL (100%) | MM8: B/F 1ST TERM | MN8: B/F 2ND TERM | MO8: GD TOTAL (300) | MP8: AV % | MQ8: GRADE | MR8: SUBJECT POSITION | MS8: CA (40) | MT8: EXAM (60) | MU8: TOTAL (100%) | MV8: B/F 1ST TERM | MW8: B/F 2ND TERM | MX8: GD TOTAL (300) | MY8: AV % | MZ8: GRADE | NA8: SUBJECT POSITION | NB8: CA (40) | NC8: EXAM (60) | ND8: TOTAL (100%) | NE8: B/F 1ST TERM | NF8: B/F 2ND TERM | NG8: GD TOTAL (300) | NH8: AV % | NI8: GRADE | NJ8: SUBJECT POSITION | NK8: CA (40) | NL8: EXAM (60) | NM8: TOTAL (100%) | NN8: B/F 1ST TERM | NO8: B/F 2ND TERM | NP8: GD TOTAL (300) | NQ8: AV % | NR8: GRADE | NS8: SUBJECT POSITION | NT8: CA (40) | NU8: EXAM (60) | NV8: TOTAL (100%) | NW8: B/F 1ST TERM | NX8: B/F 2ND TERM | NY8: GD TOTAL (300) | NZ8: AV % | OA8: GRADE | OB8: SUBJECT POSITION | OC8: CA (40) | OD8: EXAM (60) | OE8: TOTAL (100%) | OF8: B/F 1ST TERM | OG8: B/F 2ND TERM | OH8: GD TOTAL (300) | OI8: AV % | OJ8: GRADE | OK8: SUBJECT POSITION | OL8: CA (40) | OM8: EXAM (60) | ON8: TOTAL (100%) | OO8: B/F 1ST TERM | OP8: B/F 2ND TERM | OQ8: GD TOTAL (300) | OR8: AV % | OS8: GRADE | OT8: SUBJECT POSITION | OU8: TOTAL MARK | OV8: AVERAGE | OW8: CLASS POSITION
C9: 3 | D9: 4 | E9: 5 | F9: 6 | G9: 7 | H9: 8 | I9: 9 | J9: 10 | K9: 11 | L9: 12 | M9: 13 | N9: 14 | O9: 15 | P9: 16 | Q9: 17 | R9: 18 | S9: 19 | T9: 20 | U9: 21 | V9: 22 | W9: 23 | X9: 24 | Y9: 25 | Z9: 26 | AA9: 27 | AB9: 28 | AC9: 29 | AD9: 30 | AE9: 31 | AF9: 32 | AG9: 33 | AH9: 34 | AI9: 35 | AJ9: 36 | AK9: 37 | AL9: 38 | AM9: 39 | AN9: 40 | AO9: 41 | AP9: 42 | AQ9: 43 | AR9: 44 | AS9: 45 | AT9: 46 | AU9: 47 | AV9: 48 | AW9: 49 | AX9: 50 | AY9: 51 | AZ9: 52 | BA9: 53 | BB9: 54 | BC9: 55 | BD9: 56 | BE9: 57 | BF9: 58 | BG9: 59 | BH9: 60 | BI9: 61 | BJ9: 62 | BK9: 63 | BL9: 64 | BM9: 65 | BN9: 66 | BO9: 67 | BP9: 68 | BQ9: 69 | BR9: 70 | BS9: 71 | BT9: 72 | BU9: 73 | BV9: 74 | BW9: 75 | BX9: 76 | BY9: 77 | BZ9: 78 | CA9: 79 | CB9: 80 | CC9: 81 | CD9: 82 | CE9: 83 | CF9: 84 | CG9: 85 | CH9: 86 | CI9: 87 | CJ9: 88 | CK9: 89 | CL9: 90 | CM9: 91 | CN9: 92 | CO9: 93 | CP9: 94 | CQ9: 95 | CR9: 96 | CS9: 97 | CT9: 98 | CU9: 99 | CV9: 100 | CW9: 101 | CX9: 102 | CY9: 103 | CZ9: 104 | DA9: 105 | DB9: 106 | DC9: 107 | DD9: 108 | DE9: 109 | DF9: 110 | DG9: 111 | DH9: 112 | DI9: 113 | DJ9: 114 | DK9: 115 | DL9: 116 | DM9: 117 | DN9: 118 | DO9: 119 | DP9: 120 | DQ9: 121 | DR9: 122 | DS9: 123 | DT9: 124 | DU9: 125 | DV9: 126 | DW9: 127 | DX9: 128 | DY9: 129 | DZ9: 130 | EA9: 131 | EB9: 132 | EC9: 133 | ED9: 134 | EE9: 135 | EF9: 136 | EG9: 137 | EH9: 138 | EI9: 139 | EJ9: 140 | EK9: 141 | EL9: 142 | EM9: 143 | EN9: 144 | EO9: 145 | EP9: 146 | EQ9: 147 | ER9: 148 | ES9: 149 | ET9: 150 | EU9: 151 | EV9: 152 | EW9: 153 | EX9: 154 | EY9: 155 | EZ9: 156 | FA9: 157 | FB9: 158 | FC9: 159 | FD9: 160 | FE9: 161 | FF9: 162 | FG9: 163 | FH9: 164 | FI9: 165 | FJ9: 166 | FK9: 167 | FL9: 168 | FM9: 169 | FN9: 170 | FO9: 171 | FP9: 172 | FQ9: 173 | FR9: 174 | FS9: 175 | FT9: 176 | FU9: 177 | FV9: 178 | FW9: 179 | FX9: 180 | FY9: 181 | FZ9: 182 | GA9: 183 | GB9: 184 | GC9: 185 | GD9: 186 | GE9: 187 | GF9: 188 | GG9: 189 | GH9: 190 | GI9: 191 | GJ9: 192 | GK9: 193 | GL9: 194 | GM9: 195 | GN9: 196 | GO9: 197 | GP9: 198 | GQ9: 199 | GR9: 200 | GS9: 201 | GT9: 202 | GU9: 203 | GV9: 204 | GW9: 205 | GX9: 206 | GY9: 207 | GZ9: 208 | HA9: 209 | HB9: 210 | HC9: 211 | HD9: 212 | HE9: 213 | HF9: 214 | HG9: 215 | HH9: 216 | HI9: 217 | HJ9: 218 | HK9: 219 | HL9: 220 | HM9: 221 | HN9: 222 | HO9: 223 | HP9: 224 | HQ9: 225 | HR9: 226 | HS9: 227 | HT9: 228 | HU9: 229 | HV9: 230 | HW9: 231 | HX9: 232 | HY9: 233 | HZ9: 234 | IA9: 235 | IB9: 236 | IC9: 237 | ID9: 238 | IE9: 239 | IF9: 240 | IG9: 241 | IH9: 242 | II9: 243 | IJ9: 244 | IK9: 245 | IL9: 246 | IM9: 247 | IN9: 248 | IO9: 249 | IP9: 250 | IQ9: 251 | IR9: 252 | IS9: 253 | IT9: 254 | IU9: 255 | IV9: 256 | IW9: 257 | IX9: 258 | IY9: 259 | IZ9: 260 | JA9: 261 | JB9: 262 | JC9: 263 | JD9: 264 | JE9: 265 | JF9: 266 | JG9: 267 | JH9: 268 | JI9: 269 | JJ9: 270 | JK9: 271 | JL9: 272 | JM9: 273 | JN9: 274 | JO9: 275 | JP9: 276 | JQ9: 277 | JR9: 278 | JS9: 279 | JT9: 280 | JU9: 281 | JV9: 282 | JW9: 283 | JX9: 284 | JY9: 285 | JZ9: 286 | KA9: 287 | KB9: 288 | KC9: 289 | KD9: 290 | KE9: 291 | KF9: 292 | KG9: 293 | KH9: 294 | KI9: 295 | KJ9: 296 | KK9: 297 | KL9: 298 | KM9: 299 | KN9: 300 | KO9: 301 | KP9: 302 | KQ9: 303 | KR9: 304 | KS9: 305 | KT9: 306 | KU9: 307 | KV9: 308 | KW9: 309 | KX9: 310 | KY9: 311 | KZ9: 312 | LA9: 313 | LB9: 314 | LC9: 315 | LD9: 316 | LE9: 317 | LF9: 318 | LG9: 319 | LH9: 320 | LI9: 321 | LJ9: 322 | LK9: 323 | LL9: 324 | LM9: 325 | LN9: 326 | LO9: 327 | LP9: 328 | LQ9: 329 | LR9: 330 | LS9: 331 | LT9: 332 | LU9: 333 | LV9: 334 | LW9: 335 | LX9: 336 | LY9: 337 | LZ9: 338 | MA9: 339 | MB9: 340 | MC9: 341 | MD9: 342 | ME9: 343 | MF9: 344 | MG9: 345 | MH9: 346 | MI9: 347 | MJ9: 348 | MK9: 349 | ML9: 350 | MM9: 351 | MN9: 352 | MO9: 353 | MP9: 354 | MQ9: 355 | MR9: 356 | MS9: 357 | MT9: 358 | MU9: 359 | MV9: 360 | MW9: 361 | MX9: 362 | MY9: 363 | MZ9: 364 | NA9: 365 | NB9: 366 | NC9: 367 | ND9: 368 | NE9: 369 | NF9: 370 | NG9: 371 | NH9: 372 | NI9: 373 | NJ9: 374 | NK9: 375 | NL9: 376 | NM9: 377 | NN9: 378 | NO9: 379 | NP9: 380 | NQ9: 381 | NR9: 382 | NS9: 383 | NT9: 384 | NU9: 385 | NV9: 386 | NW9: 387 | NX9: 388 | NY9: 389 | NZ9: 390 | OA9: 391 | OB9: 392 | OC9: 393 | OD9: 394 | OE9: 395 | OF9: 396 | OG9: 397 | OH9: 398 | OI9: 399 | OJ9: 400 | OK9: 401 | OL9: 402 | OM9: 403 | ON9: 404 | OO9: 405 | OP9: 406 | OQ9: 407 | OR9: 408 | OS9: 409 | OT9: 410 | OU9: 411 | OV9: 412 | OW9: 413 | OX9: 414 | OY9: 415 | OZ9: 416 | PA9: 417 | PB9: 418
A10: 1 | B10: ABDULAZEEZ TOHEEB O. | C10: MALE | D10: 30 | E10: 41 | F10: =SUM(D10:E10) -> 71 | G10: =SUM(D10:E10) -> 71 | H10: =IF(G10>=75,"A",IF(G10>=60,"B",IF(G10>=50,"C",IF(G10>=40,"D",IF(G10>=35,"E","F"))))) -> B | I10: =VLOOKUP(RANK(G10,$G$10:$G$109),Sheet1!$A$381:$B$480,2,FALSE) -> 30th | J10: 21 | K10: 20 | L10: =SUM(J10:K10) -> 41 | M10: =SUM(J10:K10) -> 41 | N10: =IF(M10>=75,"A",IF(M10>=60,"B",IF(M10>=50,"C",IF(M10>=40,"D",IF(M10>=35,"E","F"))))) -> D | O10: =VLOOKUP(RANK(M10,$M$10:$M$109),Sheet1!$A$381:$B$480,2,FALSE) -> 84th | P10: 30 | Q10: 28 | R10: =SUM(P10:Q10) -> 58 | S10: =SUM(P10:Q10) -> 58 | T10: =IF(S10>=75,"A",IF(S10>=60,"B",IF(S10>=50,"C",IF(S10>=40,"D",IF(S10>=35,"E","F"))))) -> C | U10: =VLOOKUP(RANK(S10,$S$10:$S$109),Sheet1!$A$381:$B$480,2,FALSE) -> 18th | V10: 25 | W10: 35 | X10: =SUM(V10:W10) -> 60 | Y10: =SUM(V10:W10) -> 60 | Z10: =IF(Y10>=75,"A",IF(Y10>=60,"B",IF(Y10>=50,"C",IF(Y10>=40,"D",IF(Y10>=35,"E","F"))))) -> B | AA10: =VLOOKUP(RANK(Y10,$Y$10:$Y$109),Sheet1!$A$381:$B$480,2,FALSE) -> 34th | AB10: 32 | AC10: 31 | AD10: =SUM(AB10:AC10) -> 63 | AE10: =SUM(AB10:AC10) -> 63 | AF10: =IF(AE10>=75,"A",IF(AE10>=60,"B",IF(AE10>=50,"C",IF(AE10>=40,"D",IF(AE10>=35,"E","F"))))) -> B | AG10: =VLOOKUP(RANK(AE10,$AE$10:$AE$109),Sheet1!$A$381:$B$480,2,FALSE) -> 46th | AJ10: =SUM(AH10:AI10) -> 0 | AK10: =SUM(AH10:AI10) -> 0 | AL10: =IF(AK10>=75,"A",IF(AK10>=60,"B",IF(AK10>=50,"C",IF(AK10>=40,"D",IF(AK10>=35,"E","F"))))) -> F | AM10: =VLOOKUP(RANK(AK10,$AK$10:$AK$109),Sheet1!$A$381:$B$480,2,FALSE) -> 1st | AP10: =SUM(AN10:AO10) -> 0 | AQ10: =SUM(AN10:AO10) -> 0 | AR10: =IF(AQ10>=75,"A",IF(AQ10>=60,"B",IF(AQ10>=50,"C",IF(AQ10>=40,"D",IF(AQ10>=35,"E","F"))))) -> F | AS10: =VLOOKUP(RANK(AQ10,$AQ$10:$AQ$109),Sheet1!$A$381:$B$480,2,FALSE) -> 1st | AT10: 25 | AU10: 25 | AV10: =SUM(AT10:AU10) -> 50 | AW10: =SUM(AT10:AU10) -> 50 | AX10: =IF(AW10>=75,"A",IF(AW10>=60,"B",IF(AW10>=50,"C",IF(AW10>=40,"D",IF(AW10>=35,"E","F"))))) -> C | AY10: =VLOOKUP(RANK(AW10,$AW$10:$AW$109),Sheet1!$A$381:$B$480,2,FALSE) -> 58th | AZ10: 36 | BA10: 34 | BB10: =SUM(AZ10:BA10) -> 70 | BC10: =SUM(AZ10:BA10) -> 70 | BD10: =IF(BC10>=75,"A",IF(BC10>=60,"B",IF(BC10>=50,"C",IF(BC10>=40,"D",IF(BC10>=35,"E","F"))))) -> B | BE10: =VLOOKUP(RANK(BC10,$BC$10:$BC$109),Sheet1!$A$381:$B$480,2,FALSE) -> 10th | BF10: 22 | BG10: 12 | BH10: =SUM(BF10:BG10) -> 34 | BI10: =SUM(BF10:BG10) -> 34 | BJ10: =IF(BI10>=75,"A",IF(BI10>=60,"B",IF(BI10>=50,"C",IF(BI10>=40,"D",IF(BI10>=35,"E","F"))))) -> F | BK10: =VLOOKUP(RANK(BI10,$BI$10:$BI$109),Sheet1!$A$381:$B$480,2,FALSE) -> 53rd | BL10: 25 | BM10: 27 | BN10: =SUM(BL10:BM10) -> 52 | BO10: =SUM(BL10:BM10) -> 52 | BP10: =IF(BO10>=75,"A",IF(BO10>=60,"B",IF(BO10>=50,"C",IF(BO10>=40,"D",IF(BO10>=35,"E","F"))))) -> C | BQ10: =VLOOKUP(RANK(BO10,$BO$10:$BO$109),Sheet1!$A$381:$B$480,2,FALSE) -> 56th | BR10: 27 | BS10: 2 | BT10: =SUM(BR10:BS10) -> 29 | BU10: =SUM(BR10:BS10) -> 29 | BV10: =IF(BU10>=75,"A",IF(BU10>=60,"B",IF(BU10>=50,"C",IF(BU10>=40,"D",IF(BU10>=35,"E","F"))))) -> F | BW10: =VLOOKUP(RANK(BU10,$BU$10:$BU$109),Sheet1!$A$381:$B$480,2,FALSE) -> 97th | BX10: 33 | BY10: 25 | BZ10: =SUM(BX10:BY10) -> 58 | CA10: =SUM(BX10:BY10) -> 58 | CB10: =IF(CA10>=75,"A",IF(CA10>=60,"B",IF(CA10>=50,"C",IF(CA10>=40,"D",IF(CA10>=35,"E","F"))))) -> C | CC10: =VLOOKUP(RANK(CA10,$CA$10:$CA$109),Sheet1!$A$381:$B$480,2,FALSE) -> 5th | CD10: 25 | CE10: 35 | CF10: =SUM(CD10:CE10) -> 60 | CG10: =SUM(CD10:CE10) -> 60 | CH10: =IF(CG10>=75,"A",IF(CG10>=60,"B",IF(CG10>=50,"C",IF(CG10>=40,"D",IF(CG10>=35,"E","F"))))) -> B | CI10: =VLOOKUP(RANK(CG10,$CG$10:$CG$109),Sheet1!$A$381:$B$480,2,FALSE) -> 32nd | CL10: =SUM(CJ10:CK10) -> 0 | CM10: =SUM(CJ10:CK10) -> 0 | CN10: =IF(CM10>=75,"A",IF(CM10>=60,"B",IF(CM10>=50,"C",IF(CM10>=40,"D",IF(CM10>=35,"E","F"))))) -> F | CO10: =VLOOKUP(RANK(CM10,$CM$10:$CM$109),Sheet1!$A$381:$B$480,2,FALSE) -> 1st | CR10: =SUM(CP10:CQ10) -> 0 | CS10: =SUM(CP10:CQ10) -> 0 | CT10: =IF(CS10>=75,"A",IF(CS10>=60,"B",IF(CS10>=50,"C",IF(CS10>=40,"D",IF(CS10>=35,"E","F"))))) -> F | CU10: =VLOOKUP(RANK(CS10,$CS$10:$CS$109),Sheet1!$A$381:$B$480,2,FALSE) -> 1st | CX10: =SUM(CV10:CW10) -> 0 | CY10: =SUM(CV10:CW10) -> 0 | CZ10: =IF(CY10>=75,"A",IF(CY10>=60,"B",IF(CY10>=50,"C",IF(CY10>=40,"D",IF(CY10>=35,"E","F"))))) -> F | DA10: =VLOOKUP(RANK(CY10,$CY$10:$CY$109),Sheet1!$A$381:$B$480,2,FALSE) -> 1st | DC10: =CR10+CL10+CF10+BZ10+BT10+BH10+BB10+AV10+AP10+AJ10+AD10+X10+L10+F10+BN10+R10+CX10 -> 646 | DD10: =DC10/17 -> 38 | DE10: =VLOOKUP(RANK(DD10,$DD$10:$DD$109),Sheet1!$A$381:$B$480,2,FALSE) -> 40th | DF10: =CV10 -> 0 | DG10: =SUM(DC10:DD10) -> 684 | DI10: 19 | DJ10: 51 | DK10: =SUM(DI10:DJ10) -> 70 | DL10: =REPT(G10,1) -> 71 | DM10: =DK10+DL10 -> 141 | DN10: =DM10/2 -> 70.5 | DO10: =IF(DN10>=75,"A",IF(DN10>=60,"B",IF(DN10>=50,"C",IF(DN10>=40,"D",IF(DN10>=35,"E","F"))))) -> B | DP10: =VLOOKUP(RANK(DN10,$DN$10:$DN$109),Sheet1!$A$381:$B$480,2,FALSE) -> 35th | DQ10: 23 | DR10: 24 | DS10: =SUM(DQ10:DR10) -> 47 | DT10: =REPT(M10,1) -> 41 | DU10: =DS10+DT10 -> 88 | DV10: =DU10/2 -> 44 | DW10: =IF(DV10>=75,"A",IF(DV10>=60,"B",IF(DV10>=50,"C",IF(DV10>=40,"D",IF(DV10>=35,"E","F"))))) -> D | DX10: =VLOOKUP(RANK(DV10,$DV$10:$DV$109),Sheet1!$A$381:$B$480,2,FALSE) -> 76th | DY10: 28 | DZ10: 20 | EA10: =SUM(DY10:DZ10) -> 48 | EB10: =REPT(S10,1) -> 58 | EC10: =EA10+EB10 -> 106 | ED10: =EC10/2 -> 53 | EE10: =IF(ED10>=75,"A",IF(ED10>=60,"B",IF(ED10>=50,"C",IF(ED10>=40,"D",IF(ED10>=35,"E","F"))))) -> C | EF10: =VLOOKUP(RANK(ED10,$ED$10:$ED$109),Sheet1!$A$381:$B$480,2,FALSE) -> 29th | EG10: 21 | EH10: 25 | EI10: =SUM(EG10:EH10) -> 46 | EJ10: =REPT(X10,1) -> 60 | EK10: =EI10+EJ10 -> 106 | EL10: =EK10/2 -> 53 | EM10: =IF(EL10>=75,"A",IF(EL10>=60,"B",IF(EL10>=50,"C",IF(EL10>=40,"D",IF(EL10>=35,"E","F"))))) -> C | EN10: =VLOOKUP(RANK(EL10,$EL$10:$EL$109),Sheet1!$A$381:$B$480,2,FALSE) -> 53rd | EO10: 21 | EP10: 16 | EQ10: =SUM(EO10:EP10) -> 37 | ER10: =REPT(AE10,1) -> 63 | ES10: =EQ10+ER10 -> 100 | ET10: =ES10/2 -> 50 | EU10: =IF(ET10>=75,"A",IF(ET10>=60,"B",IF(ET10>=50,"C",IF(ET10>=40,"D",IF(ET10>=35,"E","F"))))) -> C | EV10: =VLOOKUP(RANK(ET10,$ET$10:$ET$109),Sheet1!$A$381:$B$480,2,FALSE) -> 60th | EY10: =SUM(EW10:EX10) -> 0 | EZ10: =REPT(AK10,1) -> 0 | FA10: =EY10+EZ10 -> 0 | FB10: =FA10/2 -> 0 | FC10: =IF(FB10>=75,"A",IF(FB10>=60,"B",IF(FB10>=50,"C",IF(FB10>=40,"D",IF(FB10>=35,"E","F"))))) -> F | FD10: =VLOOKUP(RANK(FB10,$FB$10:$FB$109),Sheet1!$A$381:$B$480,2,FALSE) -> 1st | FG10: =SUM(FE10:FF10) -> 0 | FH10: =REPT(AQ10,1) -> 0 | FI10: =FG10+FH10 -> 0 | FJ10: =FI10/2 -> 0 | FK10: =IF(FJ10>=75,"A",IF(FJ10>=60,"B",IF(FJ10>=50,"C",IF(FJ10>=40,"D",IF(FJ10>=35,"E","F"))))) -> F | FL10: =VLOOKUP(RANK(FJ10,$FJ$10:$FJ$109),Sheet1!$A$381:$B$480,2,FALSE) -> 1st | FM10: 29 | FN10: 21 | FO10: =SUM(FM10:FN10) -> 50 | FP10: =REPT(AW10,1) -> 50 | FQ10: =FO10+FP10 -> 100 | FR10: =FQ10/2 -> 50 | FS10: =IF(FR10>=75,"A",IF(FR10>=60,"B",IF(FR10>=50,"C",IF(FR10>=40,"D",IF(FR10>=35,"E","F"))))) -> C | FT10: =VLOOKUP(RANK(FR10,$FR$10:$FR$109),Sheet1!$A$381:$B$480,2,FALSE) -> 77th | FU10: 24 | FV10: 25 | FW10: =SUM(FU10:FV10) -> 49 | FX10: =REPT(BB10,1) -> 70 | FY10: =FW10+FX10 -> 119 | FZ10: =FY10/2 -> 59.5 | GA10: =IF(FZ10>=75,"A",IF(FZ10>=60,"B",IF(FZ10>=50,"C",IF(FZ10>=40,"D",IF(FZ10>=35,"E","F"))))) -> C | GB10: =VLOOKUP(RANK(FZ10,$FZ$10:$FZ$109),Sheet1!$A$381:$B$480,2,FALSE) -> 1st | GC10: 6 | GD10: 29 | GE10: =SUM(GC10:GD10) -> 35 | GF10: =REPT(BI10,1) -> 34 | GG10: =GE10+GF10 -> 69 | GH10: =GG10/2 -> 34.5 | GI10: =IF(GH10>=75,"A",IF(GH10>=60,"B",IF(GH10>=50,"C",IF(GH10>=40,"D",IF(GH10>=35,"E","F"))))) -> F | GJ10: =VLOOKUP(RANK(GH10,$GH$10:$GH$109),Sheet1!$A$381:$B$480,2,FALSE) -> 62nd | GK10: 26 | GL10: 14 | GM10: =SUM(GK10:GL10) -> 40 | GN10: =REPT(BO10,1) -> 52 | GO10: =GM10+GN10 -> 92 | GP10: =GO10/2 -> 46 | GQ10: =IF(GP10>=75,"A",IF(GP10>=60,"B",IF(GP10>=50,"C",IF(GP10>=40,"D",IF(GP10>=35,"E","F"))))) -> D | GR10: =VLOOKUP(RANK(GP10,$GP$10:$GP$109),Sheet1!$A$381:$B$480,2,FALSE) -> 82nd | GS10: 28 | GT10: 26 | GU10: =SUM(GS10:GT10) -> 54 | GV10: =REPT(BU10,1) -> 29 | GW10: =GU10+GV10 -> 83 | GX10: =GW10/2 -> 41.5 | GY10: =IF(GX10>=75,"A",IF(GX10>=60,"B",IF(GX10>=50,"C",IF(GX10>=40,"D",IF(GX10>=35,"E","F"))))) -> D | GZ10: =VLOOKUP(RANK(GX10,$GX$10:$GX$109),Sheet1!$A$381:$B$480,2,FALSE) -> 69th | HA10: 30 | HB10: 10 | HC10: =SUM(HA10:HB10) -> 40 | HD10: =REPT(CA10,1) -> 58 | HE10: =HC10+HD10 -> 98 | HF10: =HE10/2 -> 49 | HG10: =IF(HF10>=75,"A",IF(HF10>=60,"B",IF(HF10>=50,"C",IF(HF10>=40,"D",IF(HF10>=35,"E","F"))))) -> D | HH10: =VLOOKUP(RANK(HF10,$HF$10:$HF$109),Sheet1!$A$381:$B$480,2,FALSE) -> 11th | HI10: 25 | HJ10: 46 | HK10: =SUM(HI10:HJ10) -> 71 | HL10: =REPT(CG10,1) -> 60 | HM10: =HK10+HL10 -> 131 | HN10: =HM10/2 -> 65.5 | HO10: =IF(HN10>=75,"A",IF(HN10>=60,"B",IF(HN10>=50,"C",IF(HN10>=40,"D",IF(HN10>=35,"E","F"))))) -> B | HP10: =VLOOKUP(RANK(HN10,$HN$10:$HN$109),Sheet1!$A$381:$B$480,2,FALSE) -> 45th | HS10: =SUM(HQ10:HR10) -> 0 | HT10: =REPT(CM10,1) -> 0 | HU10: =HS10+HT10 -> 0 | HV10: =HU10/2 -> 0 | HW10: =IF(HV10>=75,"A",IF(HV10>=60,"B",IF(HV10>=50,"C",IF(HV10>=40,"D",IF(HV10>=35,"E","F"))))) -> F | HX10: =VLOOKUP(RANK(HV10,$HV$10:$HV$109),Sheet1!$A$381:$B$480,2,FALSE) -> 1st | IA10: =SUM(HY10:HZ10) -> 0 | IB10: =REPT(CS10,1) -> 0 | IC10: =IA10+IB10 -> 0 | ID10: =IC10/2 -> 0 | IE10: =IF(ID10>=75,"A",IF(ID10>=60,"B",IF(ID10>=50,"C",IF(ID10>=40,"D",IF(ID10>=35,"E","F"))))) -> F | IF10: =VLOOKUP(RANK(ID10,$ID$10:$ID$109),Sheet1!$A$381:$B$480,2,FALSE) -> 1st | II10: =SUM(IG10:IH10) -> 0 | IJ10: =REPT(CY10,1) -> 0 | IK10: =II10+IJ10 -> 0 | IL10: =IK10/2 -> 0 | IM10: =IF(IL10>=75,"A",IF(IL10>=60,"B",IF(IL10>=50,"C",IF(IL10>=40,"D",IF(IL10>=35,"E","F"))))) -> F | IN10: =VLOOKUP(RANK(IL10,$IL$10:$IL$109),Sheet1!$A$381:$B$480,2,FALSE) -> 1st | IO10: =ID10+HV10+HN10+HF10+GX10+GP10+GH10+FZ10+FR10+FJ10+FB10+ET10+EL10+ED10+DV10+DN10+IL10 -> 616.5 | IP10: =IO10/17 -> 36.264706 | IQ10: =VLOOKUP(RANK(IP10,$IP$10:$IP$109),Sheet1!$A$381:$B$480,2,FALSE) -> 42nd | IZ10: =SUM(IX10:IY10) -> 0 | JA10: =REPT(G10,1) -> 71 | JB10: =REPT(DK10,1) -> 70 | JC10: =IZ10+JA10+JB10 -> 141 | JD10: =JC10/3 -> 47 | JE10: =IF(JD10>=75,"A",IF(JD10>=60,"B",IF(JD10>=50,"C",IF(JD10>=40,"D",IF(JD10>=35,"E","F"))))) -> D | JF10: =VLOOKUP(RANK(JD10,$JD$10:$JD$109),Sheet1!$A$381:$B$480,2,FALSE) -> 35th | JI10: =SUM(JG10:JH10) -> 0 | JJ10: =REPT(M10,1) -> 41 | JK10: =REPT(DS10,1) -> 47 | JL10: =JI10+JJ10+JK10 -> 88 | JM10: =JL10/3 -> 29.333333 | JN10: =IF(JM10>=75,"A",IF(JM10>=60,"B",IF(JM10>=50,"C",IF(JM10>=40,"D",IF(JM10>=35,"E","F"))))) -> F | JO10: =VLOOKUP(RANK(JM10,$JM$10:$JM$109),Sheet1!$A$381:$B$480,2,FALSE) -> 76th | JR10: =SUM(JP10:JQ10) -> 0 | JS10: =REPT(S10,1) -> 58 | JT10: =REPT(EA10,1) -> 48 | JU10: =JR10+JS10+JT10 -> 106 | JV10: =JU10/3 -> 35.333333 | JW10: =IF(JV10>=75,"A",IF(JV10>=60,"B",IF(JV10>=50,"C",IF(JV10>=40,"D",IF(JV10>=35,"E","F"))))) -> E | JX10: =VLOOKUP(RANK(JV10,$JV$10:$JV$109),Sheet1!$A$381:$B$480,2,FALSE) -> 29th | KA10: =SUM(JY10:JZ10) -> 0 | KB10: =REPT(X10,1) -> 60 | KC10: =REPT(EI10,1) -> 46 | KD10: =KA10+KB10+KC10 -> 106 | KE10: =KD10/3 -> 35.333333 | KF10: =IF(KE10>=75,"A",IF(KE10>=60,"B",IF(KE10>=50,"C",IF(KE10>=40,"D",IF(KE10>=35,"E","F"))))) -> E | KG10: =VLOOKUP(RANK(KE10,$KE$10:$KE$109),Sheet1!$A$381:$B$480,2,FALSE) -> 53rd | KJ10: =SUM(KH10:KI10) -> 0 | KK10: =REPT(AD10,1) -> 63 | KL10: =REPT(EQ10,1) -> 37 | KM10: =KJ10+KK10+KL10 -> 100 | KN10: =KM10/3 -> 33.333333 | KO10: =IF(KN10>=75,"A",IF(KN10>=60,"B",IF(KN10>=50,"C",IF(KN10>=40,"D",IF(KN10>=35,"E","F"))))) -> F | KP10: =VLOOKUP(RANK(KN10,$KN$10:$KN$109),Sheet1!$A$381:$B$480,2,FALSE) -> 60th | KS10: =SUM(KQ10:KR10) -> 0 | KT10: =REPT(AK10,1) -> 0 | KU10: =REPT(EY10,1) -> 0 | KV10: =KS10+KT10+KU10 -> 0 | KW10: =KV10/3 -> 0 | KX10: =IF(KW10>=75,"A",IF(KW10>=60,"B",IF(KW10>=50,"C",IF(KW10>=40,"D",IF(KW10>=35,"E","F"))))) -> F | KY10: =VLOOKUP(RANK(KW10,$KW$10:$KW$109),Sheet1!$A$381:$B$480,2,FALSE) -> 1st | LB10: =SUM(KZ10:LA10) -> 0 | LC10: =REPT(AQ10,1) -> 0 | LD10: =REPT(FG10,1) -> 0 | LE10: =LB10+LC10+LD10 -> 0 | LF10: =LE10/3 -> 0 | LG10: =IF(LF10>=75,"A",IF(LF10>=60,"B",IF(LF10>=50,"C",IF(LF10>=40,"D",IF(LF10>=35,"E","F"))))) -> F | LH10: =VLOOKUP(RANK(LF10,$LF$10:$LF$109),Sheet1!$A$381:$B$480,2,FALSE) -> 1st | LK10: =SUM(LI10:LJ10) -> 0 | LL10: =REPT(AW10,1) -> 50 | LM10: =REPT(FO10,1) -> 50 | LN10: =LK10+LL10+LM10 -> 100 | LO10: =LN10/3 -> 33.333333 | LP10: =IF(LO10>=75,"A",IF(LO10>=60,"B",IF(LO10>=50,"C",IF(LO10>=40,"D",IF(LO10>=35,"E","F"))))) -> F | LQ10: =VLOOKUP(RANK(LO10,$LO$10:$LO$109),Sheet1!$A$381:$B$480,2,FALSE) -> 77th | LT10: =SUM(LR10:LS10) -> 0 | LU10: =REPT(BB10,1) -> 70 | LV10: =REPT(FW10,1) -> 49 | LW10: =LT10+LV10+LU10 -> 119 | LX10: =LW10/3 -> 39.666667 | LY10: =IF(LX10>=75,"A",IF(LX10>=60,"B",IF(LX10>=50,"C",IF(LX10>=40,"D",IF(LX10>=35,"E","F"))))) -> E | LZ10: =VLOOKUP(RANK(LX10,$LX$10:$LX$109),Sheet1!$A$381:$B$480,2,FALSE) -> 22nd | MC10: =SUM(MA10:MB10) -> 0 | MD10: =REPT(BI10,1) -> 34 | ME10: =REPT(GE10,1) -> 35 | MF10: =MC10+MD10+ME10 -> 69 | MG10: =MF10/3 -> 23 | MH10: =IF(MG10>=75,"A",IF(MG10>=60,"B",IF(MG10>=50,"C",IF(MG10>=40,"D",IF(MG10>=35,"E","F"))))) -> F | MI10: =VLOOKUP(RANK(MG10,$MG$10:$MG$109),Sheet1!$A$381:$B$480,2,FALSE) -> 62nd | ML10: =SUM(MJ10:MK10) -> 0 | MM10: =REPT(BO10,1) -> 52 | MN10: =REPT(GM10,1) -> 40 | MO10: =ML10+MM10+MN10 -> 92 | MP10: =MO10/3 -> 30.666667 | MQ10: =IF(MP10>=75,"A",IF(MP10>=60,"B",IF(MP10>=50,"C",IF(MP10>=40,"D",IF(MP10>=35,"E","F"))))) -> F | MR10: =VLOOKUP(RANK(MP10,$MP$10:$MP$109),Sheet1!$A$381:$B$480,2,FALSE) -> 82nd | MU10: =SUM(MS10:MT10) -> 0 | MV10: =REPT(BU10,1) -> 29 | MW10: =REPT(GU10,1) -> 54 | MX10: =MU10+MV10+MW10 -> 83 | MY10: =MX10/3 -> 27.666667 | MZ10: =IF(MY10>=75,"A",IF(MY10>=60,"B",IF(MY10>=50,"C",IF(MY10>=40,"D",IF(MY10>=35,"E","F"))))) -> F | NA10: =VLOOKUP(RANK(MY10,$MY$10:$MY$109),Sheet1!$A$381:$B$480,2,FALSE) -> 69th | ND10: =SUM(NB10:NC10) -> 0 | NE10: =REPT(CA10,1) -> 58 | NF10: =REPT(HC10,1) -> 40 | NG10: =ND10+NF10+NE10 -> 98 | NH10: =NG10/3 -> 32.666667 | NI10: =IF(NH10>=75,"A",IF(NH10>=60,"B",IF(NH10>=50,"C",IF(NH10>=40,"D",IF(NH10>=35,"E","F"))))) -> F | NJ10: =VLOOKUP(RANK(NH10,$NH$10:$NH$109),Sheet1!$A$381:$B$480,2,FALSE) -> 11th | NM10: =SUM(NK10:NL10) -> 0 | NN10: =REPT(CG10,1) -> 60 | NO10: =REPT(HK10,1) -> 71 | NP10: =NM10+NO10+NN10 -> 131 | NQ10: =NP10/3 -> 43.666667 | NR10: =IF(NQ10>=75,"A",IF(NQ10>=60,"B",IF(NQ10>=50,"C",IF(NQ10>=40,"D",IF(NQ10>=35,"E","F"))))) -> D | NS10: =VLOOKUP(RANK(NQ10,$NQ$10:$NQ$109),Sheet1!$A$381:$B$480,2,FALSE) -> 45th | NV10: =SUM(NT10:NU10) -> 0 | NW10: =REPT(CM10,1) -> 0 | NX10: =REPT(HS10,1) -> 0 | NY10: =NV10+NX10+NW10 -> 0 | NZ10: =NY10/3 -> 0 | OA10: =IF(NZ10>=75,"A",IF(NZ10>=60,"B",IF(NZ10>=50,"C",IF(NZ10>=40,"D",IF(NZ10>=35,"E","F"))))) -> F | OB10: =VLOOKUP(RANK(NZ10,$NZ$10:$NZ$109),Sheet1!$A$381:$B$480,2,FALSE) -> 1st | OE10: =SUM(OC10:OD10) -> 0 | OF10: =REPT(CS10,1) -> 0 | OG10: =REPT(IA10,1) -> 0 | OH10: =OE10+OG10+OF10 -> 0 | OI10: =OH10/3 -> 0 | OJ10: =IF(OI10>=75,"A",IF(OI10>=60,"B",IF(OI10>=50,"C",IF(OI10>=40,"D",IF(OI10>=35,"E","F"))))) -> F | OK10: =VLOOKUP(RANK(OI10,$OI$10:$OI$109),Sheet1!$A$381:$B$480,2,FALSE) -> 1st | ON10: =SUM(OL10:OM10) -> 0 | OO10: =REPT(CY10,1) -> 0 | OP10: =REPT(IL10,1) -> 0 | OQ10: =ON10+OP10+OO10 -> 0 | OR10: =OQ10/3 -> 0 | OS10: =IF(OR10>=75,"A",IF(OR10>=60,"B",IF(OR10>=50,"C",IF(OR10>=40,"D",IF(OR10>=35,"E","F"))))) -> F | OT10: =VLOOKUP(RANK(OR10,$OI$10:$OI$109),Sheet1!$A$381:$B$480,2,FALSE) -> 1st | OU10: =(OI10+NZ10+NQ10+NH10+MY10+MP10+MG10+LX10+LO10+LF10+KW10+KN10+KE10+JV10+JM10+JD10+OR10) -> 411 | OV10: =(OI10+NZ10+NQ10+NH10+MY10+MP10+MG10+LX10+LO10+LF10+KW10+KN10+KE10+JV10+JM10+JD10)/17 -> 24.176471 | OW10: =VLOOKUP(RANK(OV10,$OV$10:$OV$109),Sheet1!$A$381:$B$480,2,FALSE) -> 49th
A11: 2 | B11: ABIODUN OLAMIDE Q. | C11: MALE | D11: 31 | E11: 39 | F11: =SUM(D11:E11) -> 70 | G11: =SUM(D11:E11) -> 70 | H11: =IF(G11>=75,"A",IF(G11>=60,"B",IF(G11>=50,"C",IF(G11>=40,"D",IF(G11>=35,"E","F"))))) -> B | I11: =VLOOKUP(RANK(G11,$G$10:$G$109),Sheet1!$A$381:$B$480,2,FALSE) -> 36th | J11: 25 | K11: 20 | L11: =SUM(J11:K11) -> 45 | M11: =SUM(J11:K11) -> 45 | N11: =IF(M11>=75,"A",IF(M11>=60,"B",IF(M11>=50,"C",IF(M11>=40,"D",IF(M11>=35,"E","F"))))) -> D | O11: =VLOOKUP(RANK(M11,$M$10:$M$109),Sheet1!$A$381:$B$480,2,FALSE) -> 79th | P11: 29 | Q11: 5 | R11: =SUM(P11:Q11) -> 34 | S11: =SUM(P11:Q11) -> 34 | T11: =IF(S11>=75,"A",IF(S11>=60,"B",IF(S11>=50,"C",IF(S11>=40,"D",IF(S11>=35,"E","F"))))) -> F | U11: =VLOOKUP(RANK(S11,$S$10:$S$109),Sheet1!$A$381:$B$480,2,FALSE) -> 74th | V11: 36 | W11: 13 | X11: =SUM(V11:W11) -> 49 | Y11: =SUM(V11:W11) -> 49 | Z11: =IF(Y11>=75,"A",IF(Y11>=60,"B",IF(Y11>=50,"C",IF(Y11>=40,"D",IF(Y11>=35,"E","F"))))) -> D | AA11: =VLOOKUP(RANK(Y11,$Y$10:$Y$109),Sheet1!$A$381:$B$480,2,FALSE) -> 71st | AB11: 28 | AC11: 12 | AD11: =SUM(AB11:AC11) -> 40 | AE11: =SUM(AB11:AC11) -> 40 | AF11: =IF(AE11>=75,"A",IF(AE11>=60,"B",IF(AE11>=50,"C",IF(AE11>=40,"D",IF(AE11>=35,"E","F"))))) -> D | AG11: =VLOOKUP(RANK(AE11,$AE$10:$AE$109),Sheet1!$A$381:$B$480,2,FALSE) -> 78th | AJ11: =SUM(AH11:AI11) -> 0 | AK11: =SUM(AH11:AI11) -> 0 | AL11: =IF(AK11>=75,"A",IF(AK11>=60,"B",IF(AK11>=50,"C",IF(AK11>=40,"D",IF(AK11>=35,"E","F"))))) -> F | AM11: =VLOOKUP(RANK(AK11,$AK$10:$AK$109),Sheet1!$A$381:$B$480,2,FALSE) -> 1st | AP11: =SUM(AN11:AO11) -> 0 | AQ11: =SUM(AN11:AO11) -> 0 | AR11: =IF(AQ11>=75,"A",IF(AQ11>=60,"B",IF(AQ11>=50,"C",IF(AQ11>=40,"D",IF(AQ11>=35,"E","F"))))) -> F | AS11: =VLOOKUP(RANK(AQ11,$AQ$10:$AQ$109),Sheet1!$A$381:$B$480,2,FALSE) -> 1st | AT11: 25 | AU11: 30 | AV11: =SUM(AT11:AU11) -> 55 | AW11: =SUM(AT11:AU11) -> 55 | AX11: =IF(AW11>=75,"A",IF(AW11>=60,"B",IF(AW11>=50,"C",IF(AW11>=40,"D",IF(AW11>=35,"E","F"))))) -> C | AY11: =VLOOKUP(RANK(AW11,$AW$10:$AW$109),Sheet1!$A$381:$B$480,2,FALSE) -> 21st | AZ11: 34 | BA11: 25 | BB11: =SUM(AZ11:BA11) -> 59 | BC11: =SUM(AZ11:BA11) -> 59 | BD11: =IF(BC11>=75,"A",IF(BC11>=60,"B",IF(BC11>=50,"C",IF(BC11>=40,"D",IF(BC11>=35,"E","F"))))) -> C | BE11: =VLOOKUP(RANK(BC11,$BC$10:$BC$109),Sheet1!$A$381:$B$480,2,FALSE) -> 32nd | BF11: 13 | BG11: 14 | BH11: =SUM(BF11:BG11) -> 27 | BI11: =SUM(BF11:BG11) -> 27 | BJ11: =IF(BI11>=75,"A",IF(BI11>=60,"B",IF(BI11>=50,"C",IF(BI11>=40,"D",IF(BI11>=35,"E","F"))))) -> F | BK11: =VLOOKUP(RANK(BI11,$BI$10:$BI$109),Sheet1!$A$381:$B$480,2,FALSE) -> 74th | BL11: 26 | BM11: 28 | BN11: =SUM(BL11:BM11) -> 54 | BO11: =SUM(BL11:BM11) -> 54 | BP11: =IF(BO11>=75,"A",IF(BO11>=60,"B",IF(BO11>=50,"C",IF(BO11>=40,"D",IF(BO11>=35,"E","F"))))) -> C | BQ11: =VLOOKUP(RANK(BO11,$BO$10:$BO$109),Sheet1!$A$381:$B$480,2,FALSE) -> 23rd | BR11: 26 | BS11: 6 | BT11: =SUM(BR11:BS11) -> 32 | BU11: =SUM(BR11:BS11) -> 32 | BV11: =IF(BU11>=75,"A",IF(BU11>=60,"B",IF(BU11>=50,"C",IF(BU11>=40,"D",IF(BU11>=35,"E","F"))))) -> F | BW11: =VLOOKUP(RANK(BU11,$BU$10:$BU$109),Sheet1!$A$381:$B$480,2,FALSE) -> 88th | BX11: 34 | BY11: 10 | BZ11: =SUM(BX11:BY11) -> 44 | CA11: =SUM(BX11:BY11) -> 44 | CB11: =IF(CA11>=75,"A",IF(CA11>=60,"B",IF(CA11>=50,"C",IF(CA11>=40,"D",IF(CA11>=35,"E","F"))))) -> D | CC11: =VLOOKUP(RANK(CA11,$CA$10:$CA$109),Sheet1!$A$381:$B$480,2,FALSE) -> 20th | CD11: 30 | CE11: 45 | CF11: =SUM(CD11:CE11) -> 75 | CG11: =SUM(CD11:CE11) -> 75 | CH11: =IF(CG11>=75,"A",IF(CG11>=60,"B",IF(CG11>=50,"C",IF(CG11>=40,"D",IF(CG11>=35,"E","F"))))) -> A | CI11: =VLOOKUP(RANK(CG11,$CG$10:$CG$109),Sheet1!$A$381:$B$480,2,FALSE) -> 12th | CL11: =SUM(CJ11:CK11) -> 0 | CM11: =SUM(CJ11:CK11) -> 0 | CN11: =IF(CM11>=75,"A",IF(CM11>=60,"B",IF(CM11>=50,"C",IF(CM11>=40,"D",IF(CM11>=35,"E","F"))))) -> F | CO11: =VLOOKUP(RANK(CM11,$CM$10:$CM$109),Sheet1!$A$381:$B$480,2,FALSE) -> 1st | CR11: =SUM(CP11:CQ11) -> 0 | CS11: =SUM(CP11:CQ11) -> 0 | CT11: =IF(CS11>=75,"A",IF(CS11>=60,"B",IF(CS11>=50,"C",IF(CS11>=40,"D",IF(CS11>=35,"E","F"))))) -> F | CU11: =VLOOKUP(RANK(CS11,$CS$10:$CS$109),Sheet1!$A$381:$B$480,2,FALSE) -> 1st | CX11: =SUM(CV11:CW11) -> 0 | CY11: =SUM(CV11:CW11) -> 0 | CZ11: =IF(CY11>=75,"A",IF(CY11>=60,"B",IF(CY11>=50,"C",IF(CY11>=40,"D",IF(CY11>=35,"E","F"))))) -> F | DA11: =VLOOKUP(RANK(CY11,$CY$10:$CY$109),Sheet1!$A$381:$B$480,2,FALSE) -> 1st | DC11: =CR11+CL11+CF11+BZ11+BT11+BH11+BB11+AV11+AP11+AJ11+AD11+X11+L11+F11+BN11+R11+CX11 -> 584 | DD11: =DC11/17 -> 34.352941 | DE11: =VLOOKUP(RANK(DD11,$DD$10:$DD$109),Sheet1!$A$381:$B$480,2,FALSE) -> 62nd | DG11: =SUM(DC11:DD11) -> 618.35294 | DI11: 18 | DJ11: 35 | DK11: =SUM(DI11:DJ11) -> 53 | DL11: =REPT(G11,1) -> 70 | DM11: =DK11+DL11 -> 123 | DN11: =DM11/2 -> 61.5 | DO11: =IF(DN11>=75,"A",IF(DN11>=60,"B",IF(DN11>=50,"C",IF(DN11>=40,"D",IF(DN11>=35,"E","F"))))) -> B | DP11: =VLOOKUP(RANK(DN11,$DN$10:$DN$109),Sheet1!$A$381:$B$480,2,FALSE) -> 72nd | DQ11: 20 | DR11: 15 | DS11: =SUM(DQ11:DR11) -> 35 | DT11: =REPT(M11,1) -> 45 | DU11: =DS11+DT11 -> 80 | DV11: =DU11/2 -> 40 | DW11: =IF(DV11>=75,"A",IF(DV11>=60,"B",IF(DV11>=50,"C",IF(DV11>=40,"D",IF(DV11>=35,"E","F"))))) -> D | DX11: =VLOOKUP(RANK(DV11,$DV$10:$DV$109),Sheet1!$A$381:$B$480,2,FALSE) -> 84th | DY11: 27 | DZ11: 21 | EA11: =SUM(DY11:DZ11) -> 48 | EB11: =REPT(S11,1) -> 34 | EC11: =EA11+EB11 -> 82 | ED11: =EC11/2 -> 41 | EE11: =IF(ED11>=75,"A",IF(ED11>=60,"B",IF(ED11>=50,"C",IF(ED11>=40,"D",IF(ED11>=35,"E","F"))))) -> D | EF11: =VLOOKUP(RANK(ED11,$ED$10:$ED$109),Sheet1!$A$381:$B$480,2,FALSE) -> 65th | EG11: 21 | EH11: 33 | EI11: =SUM(EG11:EH11) -> 54 | EJ11: =REPT(X11,1) -> 49 | EK11: =EI11+EJ11 -> 103 | EL11: =EK11/2 -> 51.5 | EM11: =IF(EL11>=75,"A",IF(EL11>=60,"B",IF(EL11>=50,"C",IF(EL11>=40,"D",IF(EL11>=35,"E","F"))))) -> C | EN11: =VLOOKUP(RANK(EL11,$EL$10:$EL$109),Sheet1!$A$381:$B$480,2,FALSE) -> 57th | EO11: 27 | EP11: 22 | EQ11: =SUM(EO11:EP11) -> 49 | ER11: =REPT(AE11,1) -> 40 | ES11: =EQ11+ER11 -> 89 | ET11: =ES11/2 -> 44.5 | EU11: =IF(ET11>=75,"A",IF(ET11>=60,"B",IF(ET11>=50,"C",IF(ET11>=40,"D",IF(ET11>=35,"E","F"))))) -> D | EV11: =VLOOKUP(RANK(ET11,$ET$10:$ET$109),Sheet1!$A$381:$B$480,2,FALSE) -> 69th | EY11: =SUM(EW11:EX11) -> 0 | EZ11: =REPT(AK11,1) -> 0 | FA11: =EY11+EZ11 -> 0 | FB11: =FA11/2 -> 0 | FC11: =IF(FB11>=75,"A",IF(FB11>=60,"B",IF(FB11>=50,"C",IF(FB11>=40,"D",IF(FB11>=35,"E","F"))))) -> F | FD11: =VLOOKUP(RANK(FB11,$FB$10:$FB$109),Sheet1!$A$381:$B$480,2,FALSE) -> 1st | FG11: =SUM(FE11:FF11) -> 0 | FH11: =REPT(AQ11,1) -> 0 | FI11: =FG11+FH11 -> 0 | FJ11: =FI11/2 -> 0 | FK11: =IF(FJ11>=75,"A",IF(FJ11>=60,"B",IF(FJ11>=50,"C",IF(FJ11>=40,"D",IF(FJ11>=35,"E","F"))))) -> F | FL11: =VLOOKUP(RANK(FJ11,$FJ$10:$FJ$109),Sheet1!$A$381:$B$480,2,FALSE) -> 1st | FM11: 26 | FN11: 24 | FO11: =SUM(FM11:FN11) -> 50 | FP11: =REPT(AW11,1) -> 55 | FQ11: =FO11+FP11 -> 105 | FR11: =FQ11/2 -> 52.5 | FS11: =IF(FR11>=75,"A",IF(FR11>=60,"B",IF(FR11>=50,"C",IF(FR11>=40,"D",IF(FR11>=35,"E","F"))))) -> C | FT11: =VLOOKUP(RANK(FR11,$FR$10:$FR$109),Sheet1!$A$381:$B$480,2,FALSE) -> 40th | FU11: 38 | FV11: 30 | FW11: =SUM(FU11:FV11) -> 68 | FX11: =REPT(BB11,1) -> 59 | FY11: =SUM(FW11:FX11) -> 68 | FZ11: =FY11/2 -> 34 | GA11: =IF(FZ11>=75,"A",IF(FZ11>=60,"B",IF(FZ11>=50,"C",IF(FZ11>=40,"D",IF(FZ11>=35,"E","F"))))) -> F | GB11: =VLOOKUP(RANK(FZ11,$FZ$10:$FZ$109),Sheet1!$A$381:$B$480,2,FALSE) -> 4th | GC11: 22 | GD11: 26 | GE11: =SUM(GC11:GD11) -> 48 | GF11: =REPT(BI11,1) -> 27 | GG11: =GE11+GF11 -> 75 | GH11: =GG11/2 -> 37.5 | GI11: =IF(GH11>=75,"A",IF(GH11>=60,"B",IF(GH11>=50,"C",IF(GH11>=40,"D",IF(GH11>=35,"E","F"))))) -> E | GJ11: =VLOOKUP(RANK(GH11,$GH$10:$GH$109),Sheet1!$A$381:$B$480,2,FALSE) -> 53rd | GK11: 25 | GL11: 17 | GM11: =SUM(GK11:GL11) -> 42 | GN11: =REPT(BO11,1) -> 54 | GO11: =GM11+GN11 -> 96 | GP11: =GO11/2 -> 48 | GQ11: =IF(GP11>=75,"A",IF(GP11>=60,"B",IF(GP11>=50,"C",IF(GP11>=40,"D",IF(GP11>=35,"E","F"))))) -> D | GR11: =VLOOKUP(RANK(GP11,$GP$10:$GP$109),Sheet1!$A$381:$B$480,2,FALSE) -> 45th | GS11: 27 | GT11: 28 | GU11: =SUM(GS11:GT11) -> 55 | GV11: =REPT(BU11,1) -> 32 | GW11: =GU11+GV11 -> 87 | GX11: =GW11/2 -> 43.5 | GY11: =IF(GX11>=75,"A",IF(GX11>=60,"B",IF(GX11>=50,"C",IF(GX11>=40,"D",IF(GX11>=35,"E","F"))))) -> D | GZ11: =VLOOKUP(RANK(GX11,$GX$10:$GX$109),Sheet1!$A$381:$B$480,2,FALSE) -> 66th | HA11: 32 | HB11: 14 | HC11: =SUM(HA11:HB11) -> 46 | HD11: =REPT(CA11,1) -> 44 | HE11: =HC11+HD11 -> 90 | HF11: =HE11/2 -> 45 | HG11: =IF(HF11>=75,"A",IF(HF11>=60,"B",IF(HF11>=50,"C",IF(HF11>=40,"D",IF(HF11>=35,"E","F"))))) -> D | HH11: =VLOOKUP(RANK(HF11,$HF$10:$HF$109),Sheet1!$A$381:$B$480,2,FALSE) -> 23rd | HI11: 26 | HJ11: 41 | HK11: =SUM(HI11:HJ11) -> 67 | HL11: =REPT(CG11,1) -> 75 | HM11: =HK11+HL11 -> 142 | HN11: =HM11/2 -> 71 | HO11: =IF(HN11>=75,"A",IF(HN11>=60,"B",IF(HN11>=50,"C",IF(HN11>=40,"D",IF(HN11>=35,"E","F"))))) -> B | HP11: =VLOOKUP(RANK(HN11,$HN$10:$HN$109),Sheet1!$A$381:$B$480,2,FALSE) -> 23rd | HS11: =SUM(HQ11:HR11) -> 0 | HT11: =REPT(CM11,1) -> 0 | HU11: =HS11+HT11 -> 0 | HV11: =HU11/2 -> 0 | HW11: =IF(HV11>=75,"A",IF(HV11>=60,"B",IF(HV11>=50,"C",IF(HV11>=40,"D",IF(HV11>=35,"E","F"))))) -> F | HX11: =VLOOKUP(RANK(HV11,$HV$10:$HV$109),Sheet1!$A$381:$B$480,2,FALSE) -> 1st | IA11: =SUM(HY11:HZ11) -> 0 | IB11: =REPT(CS11,1) -> 0 | IC11: =IA11+IB11 -> 0 | ID11: =IC11/2 -> 0 | IE11: =IF(ID11>=75,"A",IF(ID11>=60,"B",IF(ID11>=50,"C",IF(ID11>=40,"D",IF(ID11>=35,"E","F"))))) -> F | IF11: =VLOOKUP(RANK(ID11,$ID$10:$ID$109),Sheet1!$A$381:$B$480,2,FALSE) -> 1st | II11: =SUM(IG11:IH11) -> 0 | IJ11: =REPT(CY11,1) -> 0 | IK11: =II11+IJ11 -> 0 | IL11: =IK11/2 -> 0 | IM11: =IF(IL11>=75,"A",IF(IL11>=60,"B",IF(IL11>=50,"C",IF(IL11>=40,"D",IF(IL11>=35,"E","F"))))) -> F | IN11: =VLOOKUP(RANK(IL11,$IL$10:$IL$109),Sheet1!$A$381:$B$480,2,FALSE) -> 1st | IO11: =ID11+HV11+HN11+HF11+GX11+GP11+GH11+FZ11+FR11+FJ11+FB11+ET11+EL11+ED11+DV11+DN11+IL11 -> 570 | IP11: =IO11/17 -> 33.529412 | IQ11: =VLOOKUP(RANK(IP11,$IP$10:$IP$109),Sheet1!$A$381:$B$480,2,FALSE) -> 56th | IZ11: =SUM(IX11:IY11) -> 0 | JA11: =REPT(G11,1) -> 70 | JB11: =REPT(DK11,1) -> 53 | JC11: =IZ11+JA11+JB11 -> 123 | JD11: =JC11/3 -> 41 | JE11: =IF(JD11>=75,"A",IF(JD11>=60,"B",IF(JD11>=50,"C",IF(JD11>=40,"D",IF(JD11>=35,"E","F"))))) -> D | JF11: =VLOOKUP(RANK(JD11,$JD$10:$JD$109),Sheet1!$A$381:$B$480,2,FALSE) -> 72nd | JI11: =SUM(JG11:JH11) -> 0 | JJ11: =REPT(M11,1) -> 45 | JK11: =REPT(DS11,1) -> 35 | JL11: =JI11+JJ11+JK11 -> 80 | JM11: =JL11/3 -> 26.666667 | JN11: =IF(JM11>=75,"A",IF(JM11>=60,"B",IF(JM11>=50,"C",IF(JM11>=40,"D",IF(JM11>=35,"E","F"))))) -> F | JO11: =VLOOKUP(RANK(JM11,$JM$10:$JM$109),Sheet1!$A$381:$B$480,2,FALSE) -> 84th | JR11: =SUM(JP11:JQ11) -> 0 | JS11: =REPT(S11,1) -> 34 | JT11: =REPT(EA11,1) -> 48 | JU11: =JR11+JS11+JT11 -> 82 | JV11: =JU11/3 -> 27.333333 | JW11: =IF(JV11>=75,"A",IF(JV11>=60,"B",IF(JV11>=50,"C",IF(JV11>=40,"D",IF(JV11>=35,"E","F"))))) -> F | JX11: =VLOOKUP(RANK(JV11,$JV$10:$JV$109),Sheet1!$A$381:$B$480,2,FALSE) -> 65th | KA11: =SUM(JY11:JZ11) -> 0 | KB11: =REPT(X11,1) -> 49 | KC11: =REPT(EI11,1) -> 54 | KD11: =KA11+KB11+KC11 -> 103 | KE11: =KD11/3 -> 34.333333 | KF11: =IF(KE11>=75,"A",IF(KE11>=60,"B",IF(KE11>=50,"C",IF(KE11>=40,"D",IF(KE11>=35,"E","F"))))) -> F | KG11: =VLOOKUP(RANK(KE11,$KE$10:$KE$109),Sheet1!$A$381:$B$480,2,FALSE) -> 57th | KJ11: =SUM(KH11:KI11) -> 0 | KK11: =REPT(AD11,1) -> 40 | KL11: =REPT(EQ11,1) -> 49 | KM11: =KJ11+KK11+KL11 -> 89 | KN11: =KM11/3 -> 29.666667 | KO11: =IF(KN11>=75,"A",IF(KN11>=60,"B",IF(KN11>=50,"C",IF(KN11>=40,"D",IF(KN11>=35,"E","F"))))) -> F | KP11: =VLOOKUP(RANK(KN11,$KN$10:$KN$109),Sheet1!$A$381:$B$480,2,FALSE) -> 69th | KS11: =SUM(KQ11:KR11) -> 0 | KT11: =REPT(AK11,1) -> 0 | KU11: =REPT(EY11,1) -> 0 | KV11: =KS11+KT11+KU11 -> 0 | KW11: =KV11/3 -> 0 | KX11: =IF(KW11>=75,"A",IF(KW11>=60,"B",IF(KW11>=50,"C",IF(KW11>=40,"D",IF(KW11>=35,"E","F"))))) -> F | KY11: =VLOOKUP(RANK(KW11,$KW$10:$KW$109),Sheet1!$A$381:$B$480,2,FALSE) -> 1st | LB11: =SUM(KZ11:LA11) -> 0 | LC11: =REPT(AQ11,1) -> 0 | LD11: =REPT(FG11,1) -> 0 | LE11: =LB11+LC11+LD11 -> 0 | LF11: =LE11/3 -> 0 | LG11: =IF(LF11>=75,"A",IF(LF11>=60,"B",IF(LF11>=50,"C",IF(LF11>=40,"D",IF(LF11>=35,"E","F"))))) -> F | LH11: =VLOOKUP(RANK(LF11,$LF$10:$LF$109),Sheet1!$A$381:$B$480,2,FALSE) -> 1st | LK11: =SUM(LI11:LJ11) -> 0 | LL11: =REPT(AW11,1) -> 55 | LM11: =REPT(FO11,1) -> 50 | LN11: =LK11+LL11+LM11 -> 105 | LO11: =LN11/3 -> 35 | LP11: =IF(LO11>=75,"A",IF(LO11>=60,"B",IF(LO11>=50,"C",IF(LO11>=40,"D",IF(LO11>=35,"E","F"))))) -> E | LQ11: =VLOOKUP(RANK(LO11,$LO$10:$LO$109),Sheet1!$A$381:$B$480,2,FALSE) -> 40th | LT11: =SUM(LR11:LS11) -> 0 | LU11: =REPT(BB11,1) -> 59 | LV11: =REPT(FW11,1) -> 68 | LW11: =LT11+LV11+LU11 -> 127 | LX11: =LW11/3 -> 42.333333 | LY11: =IF(LX11>=75,"A",IF(LX11>=60,"B",IF(LX11>=50,"C",IF(LX11>=40,"D",IF(LX11>=35,"E","F"))))) -> D | LZ11: =VLOOKUP(RANK(LX11,$LX$10:$LX$109),Sheet1!$A$381:$B$480,2,FALSE) -> 9th | MC11: =SUM(MA11:MB11) -> 0 | MD11: =REPT(BI11,1) -> 27 | ME11: =REPT(GE11,1) -> 48 | MF11: =MC11+MD11+ME11 -> 75 | MG11: =MF11/3 -> 25 | MH11: =IF(MG11>=75,"A",IF(MG11>=60,"B",IF(MG11>=50,"C",IF(MG11>=40,"D",IF(MG11>=35,"E","F"))))) -> F | MI11: =VLOOKUP(RANK(MG11,$MG$10:$MG$109),Sheet1!$A$381:$B$480,2,FALSE) -> 53rd | ML11: =SUM(MJ11:MK11) -> 0 | MM11: =REPT(BO11,1) -> 54 | MN11: =REPT(GM11,1) -> 42 | MO11: =ML11+MM11+MN11 -> 96 | MP11: =MO11/3 -> 32 | MQ11: =IF(MP11>=75,"A",IF(MP11>=60,"B",IF(MP11>=50,"C",IF(MP11>=40,"D",IF(MP11>=35,"E","F"))))) -> F | MR11: =VLOOKUP(RANK(MP11,$MP$10:$MP$109),Sheet1!$A$381:$B$480,2,FALSE) -> 45th | MU11: =SUM(MS11:MT11) -> 0 | MV11: =REPT(BU11,1) -> 32 | MW11: =REPT(GU11,1) -> 55 | MX11: =MU11+MV11+MW11 -> 87 | MY11: =MX11/3 -> 29 | MZ11: =IF(MY11>=75,"A",IF(MY11>=60,"B",IF(MY11>=50,"C",IF(MY11>=40,"D",IF(MY11>=35,"E","F"))))) -> F | NA11: =VLOOKUP(RANK(MY11,$MY$10:$MY$109),Sheet1!$A$381:$B$480,2,FALSE) -> 66th | ND11: =SUM(NB11:NC11) -> 0 | NE11: =REPT(CA11,1) -> 44 | NF11: =REPT(HC11,1) -> 46 | NG11: =ND11+NF11+NE11 -> 90 | NH11: =NG11/3 -> 30 | NI11: =IF(NH11>=75,"A",IF(NH11>=60,"B",IF(NH11>=50,"C",IF(NH11>=40,"D",IF(NH11>=35,"E","F"))))) -> F | NJ11: =VLOOKUP(RANK(NH11,$NH$10:$NH$109),Sheet1!$A$381:$B$480,2,FALSE) -> 23rd | NM11: =SUM(NK11:NL11) -> 0 | NN11: =REPT(CG11,1) -> 75 | NO11: =REPT(HK11,1) -> 67 | NP11: =NM11+NO11+NN11 -> 142 | NQ11: =NP11/3 -> 47.333333 | NR11: =IF(NQ11>=75,"A",IF(NQ11>=60,"B",IF(NQ11>=50,"C",IF(NQ11>=40,"D",IF(NQ11>=35,"E","F"))))) -> D | NS11: =VLOOKUP(RANK(NQ11,$NQ$10:$NQ$109),Sheet1!$A$381:$B$480,2,FALSE) -> 23rd | NV11: =SUM(NT11:NU11) -> 0 | NW11: =REPT(CM11,1) -> 0 | NX11: =REPT(HS11,1) -> 0 | NY11: =NV11+NX11+NW11 -> 0 | NZ11: =NY11/3 -> 0 | OA11: =IF(NZ11>=75,"A",IF(NZ11>=60,"B",IF(NZ11>=50,"C",IF(NZ11>=40,"D",IF(NZ11>=35,"E","F"))))) -> F | OB11: =VLOOKUP(RANK(NZ11,$NZ$10:$NZ$109),Sheet1!$A$381:$B$480,2,FALSE) -> 1st | OE11: =SUM(OC11:OD11) -> 0 | OF11: =REPT(CS11,1) -> 0 | OG11: =REPT(IA11,1) -> 0 | OH11: =OE11+OG11+OF11 -> 0 | OI11: =OH11/2 -> 0 | OJ11: =IF(OI11>=75,"A",IF(OI11>=60,"B",IF(OI11>=50,"C",IF(OI11>=40,"D",IF(OI11>=35,"E","F"))))) -> F | OK11: =VLOOKUP(RANK(OI11,$OI$10:$OI$109),Sheet1!$A$381:$B$480,2,FALSE) -> 1st | ON11: =SUM(OL11:OM11) -> 0 | OO11: =REPT(CY11,1) -> 0 | OP11: =REPT(IL11,1) -> 0 | OQ11: =ON11+OP11+OO11 -> 0 | OR11: =OQ11/3 -> 0 | OS11: =IF(OR11>=75,"A",IF(OR11>=60,"B",IF(OR11>=50,"C",IF(OR11>=40,"D",IF(OR11>=35,"E","F"))))) -> F | OT11: =VLOOKUP(RANK(OR11,$OI$10:$OI$109),Sheet1!$A$381:$B$480,2,FALSE) -> 1st | OU11: =(OI11+NZ11+NQ11+NH11+MY11+MP11+MG11+LX11+LO11+LF11+KW11+KN11+KE11+JV11+JM11+JD11+OR11) -> 399.66667 | OV11: =(OI11+NZ11+NQ11+NH11+MY11+MP11+MG11+LX11+LO11+LF11+KW11+KN11+KE11+JV11+JM11+JD11)/17 -> 23.509804 | OW11: =VLOOKUP(RANK(OV11,$OV$10:$OV$109),Sheet1!$A$381:$B$480,2,FALSE) -> 56th
